Workbook

Sheet 36-SÜLSER-SIVA-AZ&mlen41
A1: Layer | B1: Length
A2: 1.3.1._SÜLSER_ÇİMENTOSIVA_DA_D20_H_4.80 (-4.70 +0.30) | B2: 6124.0014
A3: 1.3.1._SÜLSER_ÇİMENTOSIVA_KA_0.60_H_3.95 (-4.70 +0.30) | B3: 100
A4: 1.3.1._SÜLSER_ÇİMENTOSIVA_KA_0.60_H_4.40 (-4.70 +0.30) | B4: 584
A5: 1.3.1._SÜLSER_ÇİMENTOSIVA_KA_0.80_H_1.75 (-4.70 +0.30) KAPI | B5: 210
A6: 1.3.1._SÜLSER_ÇİMENTOSIVA_KA_0.80_H_4.20 (-4.70 +0.30) | B6: 494

Sheet tüm duvarlar
C3: MERDİVEN DUVAR SIVA METRAJLARI
C4: Kat | D4: Açıklama | E4: Adet | F4: Uzunluk | G4: Yükseklik | H4: Toplam
C5: 5.KAT | D5: 1.3.2._SÜLSER_ALÇISIVA_DA_D20_H_1.65 (+25.30 +30.20) | E5: 1 | F5: 2 | G5: 1.65 | H5: =+F5*G5*E5 -> 3.3
C6: 5.KAT | D6: 1.3.2._SÜLSER_ALÇISIVA_DA_D20_H_4.25 (+25.30 +30.20) | E6: 1 | F6: 1 | G6: 4.25 | H6: =+F6*G6*E6 -> 4.25
C7: 5.KAT | D7: 1.3.2._SÜLSER_ALÇISIVA_DA_D20_H_4.70 (+25.30 +30.20) | E7: 1 | F7: 67.2201 | G7: 4.7 | H7: =+F7*G7*E7 -> 315.93447
C8: 5.KAT | D8: 1.3.2._SÜLSER_ALÇISIVA_KA_0.80_H_1.10 (+25.30 +30.20) | E8: 1 | F8: 2.3 | G8: 1.1 | H8: =+F8*G8*E8 -> 2.53
C9: 5.KAT | D9: 1.3.2._SÜLSER_ALÇISIVA_KA_0.80_H_4.10 (+25.30 +30.20) | E9: 1 | F9: 4.74 | G9: 4.1 | H9: =+F9*G9*E9 -> 19.434
C11: 4-3-2-1-ZEMİN KATLAR | D11: 1.3.2._SÜLSER_ALÇISIVA_DA_D20_H_1.65 (+0.30 +5.30) | E11: 5 | F11: 2 | G11: 1.75 | H11: =+F11*G11*E11 -> 17.5
D12: 1.3.2._SÜLSER_ALÇISIVA_DA_D20_H_4.35 (+0.30 +5.30) | E12: 5 | F12: 1 | G12: 4.35 | H12: =+F12*G12*E12 -> 21.75
D13: 1.3.2._SÜLSER_ALÇISIVA_DA_D20_H_4.80 (+0.30 +5.30) | E13: 5 | F13: 65.0796 | G13: 4.8 | H13: =+F13*G13*E13 -> 1561.9104
D14: 1.3.2._SÜLSER_ALÇISIVA_KA_0.80_H_1.15 (+0.30 +5.30) | E14: 5 | F14: 2.3 | G14: 1.15 | H14: =+F14*G14*E14 -> 13.225
D15: 1.3.2._SÜLSER_ALÇISIVA_KA_0.80_H_4.20 (+0.30 +5.30) | E15: 5 | F15: 4.74 | G15: 4.2 | H15: =+F15*G15*E15 -> 99.54
C16: 1.3.2 ALÇI SIVA TOPLAM | H16: =+SUM(H5:H15) -> 2059.3739
C18: AZ KATI | D18: 1.3.1._SÜLSER_ÇİMENTOSIVA_DA_D20_H_4.80 (-4.70 +0.30) | E18: 1 | F18: 61.240014 | G18: 4.8 | H18: =+F18*G18*E18 -> 293.95207
C19: AZ KATI | D19: 1.3.1._SÜLSER_ÇİMENTOSIVA_KA_0.60_H_3.95 (-4.70 +0.30) | E19: 1 | F19: 1 | G19: 3.95 | H19: =+F19*G19*E19 -> 3.95
C20: AZ KATI | D20: 1.3.1._SÜLSER_ÇİMENTOSIVA_KA_0.60_H_4.40 (-4.70 +0.30) | E20: 1 | F20: 5.84 | G20: 4.4 | H20: =+F20*G20*E20 -> 25.696
C21: AZ KATI | D21: 1.3.1._SÜLSER_ÇİMENTOSIVA_KA_0.80_H_1.75 (-4.70 +0.30) KAPI | E21: 1 | F21: 2.1 | G21: 1.75 | H21: =+F21*G21*E21 -> 3.675
C22: AZ KATI | D22: 1.3.1._SÜLSER_ÇİMENTOSIVA_KA_0.80_H_4.20 (-4.70 +0.30) | E22: 1 | F22: 4.94 | G22: 4.2 | H22: =+F22*G22*E22 -> 20.748
C24: B1 KATI | D24: 1.3.1_SÜLSER_ÇİMENTOSIVA_DA_D20_H.0.62 (-10.2 -4.70) | E24: 1 | F24: 7.12 | G24: 2.95 | H24: =+F24*G24*E24 -> 21.004
C25: B1 KATI | D25: 1.3.1_SÜLSER_ÇİMENTOSIVA_DA_D20_H.1.25 (-10.2 -4.70) | E25: 1 | F25: 6.624791 | G25: 4.05 | H25: =+F25*G25*E25 -> 26.830404
C26: B1 KATI | D26: 1.3.1_SÜLSER_ÇİMENTOSIVA_DA_D20_H.2.95 KAPI (-10.2 -4.70) | E26: 1 | F26: 2.099579 | G26: 4.68 | H26: =+F26*G26*E26 -> 9.8260297
C27: B1 KATI | D27: 1.3.1_SÜLSER_ÇİMENTOSIVA_DA_D20_H.4.05 (-10.2 -4.70) | E27: 1 | F27: 23.76 | G27: 5.3 | H27: =+F27*G27*E27 -> 125.928
C28: B1 KATI | D28: 1.3.1_SÜLSER_ÇİMENTOSIVA_DA_D20_H.4.68 (-10.2 -4.70) | E28: 1 | F28: 8.2 | G28: 2.35 | H28: =+F28*G28*E28 -> 19.27
C29: B1 KATI | D29: 1.3.1_SÜLSER_ÇİMENTOSIVA_DA_D20_H.5.30 (-10.2 -4.70) | E29: 1 | F29: 31.620421 | G29: 4.7 | H29: =+F29*G29*E29 -> 148.61598
C30: B1 KATI | D30: 1.3.1_SÜLSER_ÇİMENTOSIVA_KA_0.80_H.2.35 (-10.2 -4.70) KAPI | E30: 1 | F30: 2.099579 | G30: 2.35 | H30: =+F30*G30*E30 -> 4.9340107
C31: B1 KATI | D31: 1.3.1_SÜLSER_ÇİMENTOSIVA_KA_0.80_H.4.70 (-10.2 -4.70) | E31: 1 | F31: 4.940421 | G31: 4.7 | H31: =+F31*G31*E31 -> 23.219979
H32: =+F32*G32*E32 -> 0
C33: 1.3.1 ÇİMENTO ESASLI TOPLAM | H33: =+SUM(H18:H32) -> 727.64947
D35: SARFİYAT HESABI (2 cm kalınlık için)
D36: Malzeme | E36: Birim | F36: Kullanılması Gereken Miktar | G36: Sarfiyat (2 cm) | H36: Toplam Kg
D37: ALÇITEK TORO(1 cm kalınlık için 10.5 kg/m²) | E37: kg | F37: =+H16 -> 2059.3739 | G37: =10.5*2 -> 21 | H37: =+F37*G37 -> 43246.851
D38: GRİO MATİK (1 cm kalınlık için 14-17 kg/m²) | E38: kg | F38: =+H33 -> 727.64947 | G38: =15*2 -> 30 | H38: =+F38*G38 -> 21829.484
B41: KULLANILAN MİKTAR
B42: 1 Palette 35 kg ağırlığında 48 adet torba bulunmaktadır
B43: Malzeme | D43: Mahal | E43: Birim | F43: Kullanılan Palet Miktarı | H43: Toplam Kg
B44: ALÇITEK TORO | D44: MC10 | E44: kg | F44: 17 | G44: PALET | H44: =+F44*48*35 -> 28560
B45: ALÇITEK TORO | D45: MC11 | E45: kg | F45: 18 | G45: PALET | H45: =+F45*48*35 -> 30240
B46: ALÇITEK TORO | D46: MC06 | E46: kg | F46: 14 | G46: PALET | H46: =+F46*48*35 -> 23520
B47: ALÇITEK TORO | D47: MC19 | E47: kg | F47: 14 | G47: PALET | H47: =+F47*48*35 -> 23520
B48: TOPLAM KULLANILAN ALÇITEK TORO | H48: =+SUM(H44:H47) -> 105840
...

Sheet İLAVE İS TUT.
B3: İLAVE İŞLER / KESİNTİ - YEVMİYE TUTANAĞI
B5: Tarih: | D5: 46289 | H5: Proje Adı: | I5: ANKARA ADALET SARAYI YAPIM İŞİ
B7: Tutanak No: | D7: 267 | H7: Bina: | I7: C BLOK
B9: Alt Yüklenici: | D9: Sülser Müh. İnş Nak. Elk. Mek. San. Ve Tic. Ltd. Şti. | H9: Blok / Kat / Mahal | I9: C5/ 0.20/MC10,MC11,MC06,MC19
H10: * Mahal kodu belirtilmeyen tutanaklar işleme alınmayacaktır.
B12: İlave İşin Tanımı:
B15: İlave İşin Gerekçesi : * Rönesans uygulama sorumlusu tarafından doldurulacaktır. | F15: Kapsam dışı ilave işler
F17: Proje revizyonu
F19: İmalatlara verilen zarar. Kesinti yapılacak firma :
F21: Başka bir altyüklenici hatası. Kesinti yapılacak firma :
F23: Başka bir altyüklenici nam-ı hesabına iş. Kesinti yapılacak firma :
F25: Rönesans süpervizyon hatası. Altyüklenicilerden rücu edilmeyecek.
B27: Açıklama : | E27: * Yüklenici tarafından doldurulacaktır.
E28: C3 Blok MC10- C5 Blok MC06,MC11,MC19 merdivenlerinde yapılan ölçümler ve uygulama sırasında, kaba inşaat imalatlarındaki yüzey bozuklukları nedeniyle duvar alçı sıva kalınlıkları proje ve standart uygulama kalınlıklarının üzerine çıkmış olup yer yer 5-8 cm seviyelerine ulaşmıştır.
E32: * Rönesans uygulama sorumlusu tarafından doldurulacaktır.
B38: Ekler: | D38: 1. Ataşmanlar (Çizimler) | F38: 2. Fotoğraflar | I38: 3. Diğer Belgeler (e-posta v.b)
B40: * İşçilik yevmiyelerinde şahısın usta yada usta yardımcısı olduğu belirtilmelidir. Örnek: Ahmet Yılmaz (Usta) veya Ali Demir (Usta Yardımcısı) gibi
B41: A) | C41: ***İLAVE İŞLERE KONU ALTYÜKLENİCİ FİRMA TARAFINDAN ALINAN MALZEME / İŞÇİLİK KALEMLERİ
B42: No | C42: İşin Cinsi (İşçilik, Malzeme, Ekipman) | E42: İşin Gerçekleşme Tarihi | F42: Birim | G42: Miktar | H42: Birim Fiyat | J42: Toplam Fiyat
B43: 1 | C43: 1.3.2 Duvarlara Alçı Sıva Yapılması | E43: =+$D$5 -> 46289 | F43: m² | G43: =+'tüm duvarlar'!H53 -> 2980.6261 | J43: =+H43*G43 -> 0
B44: 2 | C44: 1.3.1 Duvarlara Çimento Esaslı Sıva Yapılması | E44: =+$D$5 -> 46289 | F44: m² | G44: =+'tüm duvarlar'!H54 -> 672.35053 | J44: =+H44*G44 -> 0
B45: 3 | J45: =+H45*G45 -> 0
B46: 4 | J46: =+H46*G46 -> 0
B47: 5 | J47: =+H47*G47 -> 0
B48: 6 | J48: =+H48*G48 -> 0
B49: 7 | J49: =+H49*G49 -> 0
B50: 8 | J50: =+H50*G50 -> 0
B51: 9 | J51: =+H51*G51 -> 0
B52: 10 | J52: =+H52*G52 -> 0
B53: Ara Toplam | J53: =+SUM(J43:L52) -> 0
B54: B) | C54: ***REC TARAFINDAN TEMİN EDİLEN MALZEME / İŞÇİLİK KALEMLERİ
B55: No | C55: İşin Cinsi (İşçilik, Malzeme, Ekipman) | E55: İşin Gerçekleşme Tarihi | F55: Birim | G55: Miktar | H55: Birim Fiyat | J55: Toplam Fiyat
B56: 1 | J56: =+H56*G56 -> 0
B57: 2 | J57: =+H57*G57 -> 0
B58: 3 | J58: =+H58*G58 -> 0
B59: 4 | J59: =+H59*G59 -> 0
B60: 5 | J60: =+H60*G60 -> 0
B61: Ara Toplam | J61: =+SUM(J56:L60) -> 0
B62: Genel Toplam | J62: =+J61+J53 -> 0
B64: İLAVE İŞİ YAPAN ALT YÜKLENİCİ | F64: KESİNTİ YAPILACAK ALT YÜKLENİCİ | I64: RÖNESANS UYGULAMA SORUMLUSU
...

Sheet İLAVE İS TUT. (2)
B3: İLAVE İŞLER / KESİNTİ - YEVMİYE TUTANAĞI EK
B5: Tarih: | D5: ='İLAVE İS TUT.'!D5 -> 46289 | H5: Proje Adı: | I5: ANKARA ADALET SARAYI YAPIM İŞİ
B7: Tutanak No: | D7: ='İLAVE İS TUT.'!D7 -> 267 | H7: Bina: | I7: C BLOK
B9: Alt Yüklenici: | D9: Sülser Müh. İnş Nak. Elk. Mek. San. Ve Tic. Ltd. Şti. | H9: Blok / Kat / Mahal | I9: ='İLAVE İS TUT.'!I9 -> C5/ 0.20/MC10,MC11,MC06,MC19
