Workbook

Sheet İşleyiş Prosedürü
B3: İLAVE İŞLER TUTANAĞI İŞLEYİŞ PROSEDÜRÜ
B4: 1. | C4: İlave işler tutanağı yüklenici tarafından hazırlanır. (3 gün içinde)
B5: 2. | C5: İlk imzaları Rönesans Uygulama Sorumlusu (İşi Yaptıran) ve Şantiye Şefi atar.
B6: 3. | C6: ŞŞ imzasından sonra tutanak Teknik Ofise gelir. Tutanak numarası verilir. Tutanak ilave işler takip tablosuna işlenir. (İşin gerçekleşme tarihinden sonra 7 gün içinde teknik ofise ulaşmayan tutanaklar işleme alınmayacaktır.)
B7: 4. | C7: Proje revizyonundan kaynaklı bir tutanak ise Dizayn Ofisin imzası alınır.
B8: 5. | C8: Teknik ofisin imzasından sonra Tutanak sırasıyla PMY – PM imzalarına çıkarılır.
B9: 6. | C9: Tutanakta diğer birimlere ait kesinti var ise Şantiye Şefinin imzasından sonra Elektrik ve Mekanik birim şeflerinin imzasına sunulur.
B10: 7. | C10: Proje müdürünün imzasından sonra tutanak üzerindeki değişiklikler Teknik Ofis tarafından kontrol edilir ve kesin kayıt yapılır.
B11: 8. | C11: Tutanak PMY'lerin imzasına gelene kadar süreçleri Yüklenici takip edecektir.
B12: 9. | C12: Ödeme kalemlerinde YEVMİYE üzeinden hesap bulunması durumun da "PERSONEL VE ÇALIŞMA İLİŞKİLERİ BİRİMİ" tarafından imzaltılmayan tutanklar işleme alınmayacaktır.
B13: 10. | C13: REC bünyesinde yapılan malzeme ve işçilik kalemleri bulunması durumunda ekli tutanağa işlenecek İlave İşi Yapan firmaya ödeme yapılmayacaktır.
B14: 11. | C14: Örnek ilave işler tutanağı bu dosyanın ikinci sayfasındadır.

Sheet İLAVE İS TUT.
B3: İLAVE İŞLER / KESİNTİ - YEVMİYE TUTANAĞI
B5: Tarih: | D5: 46110 | H5: Proje Adı: | I5: ANKARA ADALET SARAYI YAPIM İŞİ
B7: Tutanak No: | D7: 092 | H7: Bina: | I7: C BLOK
B9: Alt Yüklenici: | D9: Sülser Müh. İnş Nak. Elk. Mek. San. Ve Tic. Ltd. Şti. | H9: Blok / Kat / Mahal | I9: C3/MC03
H10: * Mahal kodu belirtilmeyen tutanaklar işleme alınmayacaktır.
B12: İlave İşin Tanımı:
B15: İlave İşin Gerekçesi : * Rönesans uygulama sorumlusu tarafından doldurulacaktır. | F15: Kapsam dışı ilave işler
F17: Proje revizyonu
F19: İmalatlara verilen zarar. Kesinti yapılacak firma :
F21: Başka bir altyüklenici hatası. Kesinti yapılacak firma :
F23: Başka bir altyüklenici nam-ı hesabına iş. Kesinti yapılacak firma :
F25: Rönesans süpervizyon hatası. Altyüklenicilerden rücu edilmeyecek.
B27: Açıklama : | E27: * Yüklenici tarafından doldurulacaktır.
E28: C3 Blok MC03 merdiveninde, alçı sıva imalatı öncesinde tüm katlar boyunca gerekli beton kırımları yapılmıştır.
E32: * Rönesans uygulama sorumlusu tarafından doldurulacaktır.
B38: Ekler: | D38: 1. Ataşmanlar (Çizimler) | F38: 2. Fotoğraflar | I38: 3. Diğer Belgeler (e-posta v.b)
B40: * İşçilik yevmiyelerinde şahısın usta yada usta yardımcısı olduğu belirtilmelidir. Örnek: Ahmet Yılmaz (Usta) veya Ali Demir (Usta Yardımcısı) gibi
B41: A) | C41: ***İLAVE İŞLERE KONU ALTYÜKLENİCİ FİRMA TARAFINDAN ALINAN MALZEME / İŞÇİLİK KALEMLERİ
B42: No | C42: İşin Cinsi (İşçilik, Malzeme, Ekipman) | E42: İşin Gerçekleşme Tarihi | F42: Birim | G42: Miktar | H42: Birim Fiyat | J42: Toplam Fiyat
B43: 1 | C43: MEHMET SİNAN MENCİK (USTA) | E43: =D$5 -> 46110 | F43: Yevmiye | G43: 0.5 | J43: =+H43*G43 -> 0
B44: 2 | C44: İBRAHİM MENCİK (USTA) | E44: =D$5 -> 46110 | F44: Yevmiye | G44: 0.5 | J44: =+H44*G44 -> 0
B45: 3 | C45: ERCAN MENCİK (USTA) | E45: =D$5 -> 46110 | F45: Yevmiye | G45: 0.5 | J45: =+H45*G45 -> 0
B46: 4 | C46: MEHMET ÇALAĞAN (USTA) | E46: 46111 | F46: Yevmiye | G46: 0.5 | J46: =+H46*G46 -> 0
B47: 5 | C47: ABDULKADİR IŞIK (USTA) | E47: 46111 | F47: Yevmiye | G47: 0.5 | J47: =+H47*G47 -> 0
B48: 6 | C48: ERCAN MENCİK (USTA) | E48: 46111 | F48: Yevmiye | G48: 0.5 | J48: =+H48*G48 -> 0
B49: 7 | C49: MEHMET ÇALAĞAN (USTA) | E49: 46112 | F49: Yevmiye | G49: 0.5 | J49: =+H49*G49 -> 0
B50: 8 | C50: İBRAHİM MENCİK (USTA) | E50: 46112 | F50: Yevmiye | G50: 0.5 | J50: =+H50*G50 -> 0
B51: 9 | C51: ERCAN MENCİK (USTA) | E51: 46112 | F51: Yevmiye | G51: 0.5 | J51: =+H51*G51 -> 0
B52: 1 | C52: MEHMET SİNAN MENCİK (USTA) | E52: 46113 | F52: Yevmiye | G52: 0.5 | J52: =+H52*G52 -> 0
B53: 2 | C53: İBRAHİM MENCİK (USTA) | E53: 46113 | F53: Yevmiye | G53: 0.5 | J53: =+H53*G53 -> 0
B54: 3 | C54: ERCAN MENCİK (USTA) | E54: 46113 | F54: Yevmiye | G54: 0.5 | J54: =+H54*G54 -> 0
B55: Ara Toplam | J55: =+SUM(J43:L51) -> 0
B56: B) | C56: ***REC TARAFINDAN TEMİN EDİLEN MALZEME / İŞÇİLİK KALEMLERİ
B57: No | C57: İşin Cinsi (İşçilik, Malzeme, Ekipman) | E57: İşin Gerçekleşme Tarihi | F57: Birim | G57: Miktar | H57: Birim Fiyat | J57: Toplam Fiyat
B58: 1 | J58: =+H58*G58 -> 0
B59: 2 | J59: =+H59*G59 -> 0
B60: 3 | J60: =+H60*G60 -> 0
B61: 4 | J61: =+H61*G61 -> 0
B62: 5 | J62: =+H62*G62 -> 0
B63: Ara Toplam | J63: =+SUM(J58:L62) -> 0
...

Sheet İLAVE İS TUT. (2)
B3: İLAVE İŞLER / KESİNTİ - YEVMİYE TUTANAĞI EK
B5: Tarih: | D5: ='İLAVE İS TUT.'!D5 -> 46110 | H5: Proje Adı: | I5: ANKARA ADALET SARAYI YAPIM İŞİ
B7: Tutanak No: | D7: ='İLAVE İS TUT.'!D7 -> 092 | H7: Bina: | I7: C BLOK
B9: Alt Yüklenici: | D9: Sülser Müh. İnş Nak. Elk. Mek. San. Ve Tic. Ltd. Şti. | H9: Blok / Kat / Mahal | I9: ='İLAVE İS TUT.'!I9 -> C3/MC03

Sheet İLAVE İS TUT. (3)
B3: İLAVE İŞLER / KESİNTİ - YEVMİYE TUTANAĞI EK
B5: Tarih: | D5: ='İLAVE İS TUT.'!D5 -> 46110 | H5: Proje Adı: | I5: ANKARA ADALET SARAYI YAPIM İŞİ
B7: Tutanak No: | D7: ='İLAVE İS TUT.'!D7 -> 092 | H7: Bina: | I7: C BLOK
B9: Alt Yüklenici: | D9: Sülser Müh. İnş Nak. Elk. Mek. San. Ve Tic. Ltd. Şti. | H9: Blok / Kat / Mahal | I9: ='İLAVE İS TUT.'!I9 -> C3/MC03
